#VRML_SIM R2020a utf8
WorldInfo {
}
Viewpoint {
  orientation 0.06876924543165334 -0.9961918285986238 -0.053596935696838266 4.955410225401478
  position 2.3848919549049943 0.3554901068634635 -0.030563042437283805
  follow "robot(2):camera"
  followType "None"
}
TexturedBackground {
}
TexturedBackgroundLight {
}
RectangleArena {
  translation -0.0184391 -1.11022e-16 0.00478503
  floorSize 3.5 3.5
  wallThickness 0.02
  wallHeight -1
}
Robot {
  translation 1.1078140706417361e-05 0.15800921851784808 -1.6944956896024505e-06
  rotation 0.0006224335478898247 0.0009860384458512414 -0.9999993201520999 -0.009530896986756514
  children [
    DEF ROOF HingeJoint {
      jointParameters HingeJointParameters {
      }
      endPoint Solid {
        translation 0 0.12 0
        children [
          Shape {
            appearance PBRAppearance {
              baseColor 0 0.1 1
              roughness 1
              metalness 0
            }
            geometry Cone {
              bottomRadius 0.1
              height 0.05
            }
          }
        ]
        name "solid(3)"
      }
    }
    DEF SENSORS HingeJoint {
      jointParameters HingeJointParameters {
      }
      endPoint Solid {
        translation 0 0 0.19
        children [
          DEF BALL_SENSOR1 HingeJoint {
            endPoint Solid {
              translation 0 0 -0.09
              children [
                LightSensor {
                  translation 0 0 0.01
                }
                Shape {
                  appearance PBRAppearance {
                  }
                  geometry Sphere {
                    radius 0.01
                  }
                }
              ]
            }
          }
          DEF BALL_SENSOR4 HingeJoint {
            endPoint Solid {
              translation 0 0 -0.29
              children [
                LightSensor {
                  translation 0 0 -0.01
                  rotation 0 1 0 -3.1415853071795863
                }
                Shape {
                  appearance PBRAppearance {
                  }
                  geometry Sphere {
                    radius 0.01
                  }
                }
              ]
              name "solid(1)"
            }
          }
          DEF BALL_SENSOR3 HingeJoint {
            endPoint Solid {
              translation 0.08 0 -0.25
              children [
                LightSensor {
                  translation 0.00500009 0 -0.0013398
                  rotation 0 -1 0 -2.094405307179586
                }
                Shape {
                  appearance PBRAppearance {
                  }
                  geometry Sphere {
                    radius 0.01
                  }
                }
              ]
              name "solid(4)"
            }
          }
          DEF BALL_SENSOR2 HingeJoint {
            endPoint Solid {
              translation 0.08 0 -0.13
              children [
                LightSensor {
                  translation 0.00499999 0 0.00865999
                  rotation 0 -1 0 -1.0472053071795866
                }
                Shape {
                  appearance PBRAppearance {
                  }
                  geometry Sphere {
                    radius 0.01
                  }
                }
              ]
              name "solid(2)"
            }
          }
          DEF BALL_SENSOR6 HingeJoint {
            endPoint Solid {
              translation -0.08 0 -0.13
              children [
                LightSensor {
                  translation -0.00965926 0 -0.00258843
                  rotation 0 1 0 -1.3089953071795861
                }
                Shape {
                  appearance PBRAppearance {
                  }
                  geometry Sphere {
                    radius 0.01
                  }
                }
              ]
              name "solid(5)"
            }
          }
          DEF BALL_SENSOR5 HingeJoint {
            endPoint Solid {
              translation -0.08 0 -0.25
              children [
                LightSensor {
                  translation -0.00465919 0 -0.00392793
                  rotation -9.58979e-09 1 7.35855e-09 -1.8325853071795866
                }
                Shape {
                  appearance PBRAppearance {
                  }
                  geometry Sphere {
                    radius 0.01
                  }
                }
              ]
              name "solid(3)"
            }
          }
        ]
        name "solid(2)"
      }
    }
    DEF WHEEL_BACK HingeJoint {
      jointParameters HingeJointParameters {
        position -0.00021596930764522968
      }
      endPoint Solid {
        translation -0.04999999999999977 -0.11999999720143519 2.5916316715959513e-05
        rotation 1 0 0 2.6461529891514695
        children [
          DEF SPHERE Shape {
            appearance PBRAppearance {
            }
            geometry DEF SPHERE_GEOMETRY Sphere {
              radius 0.041
              subdivision 2
            }
          }
        ]
        name "solid(1)"
        boundingObject USE SPHERE
        physics Physics {
        }
      }
    }
    DEF WHEEL_1 HingeJoint {
      jointParameters HingeJointParameters {
        position -2.3190225372633176e-06
        anchor 0 -0.12 0.04
      }
      device [
        RotationalMotor {
          name "right wheel motor"
        }
      ]
      endPoint DEF WHEEL_21 Solid {
        translation 0.01999999999999996 -0.11999995361954925 0.05999999999994615
        rotation 1 0 0 1.5707973748943318
        children [
          DEF WHEEL2 Shape {
            appearance PBRAppearance {
              baseColor 0 0 1
              roughness 1
              metalness 0
            }
            geometry Cylinder {
              height 0.01
              radius 0.04
            }
          }
        ]
        boundingObject USE WHEEL2
        physics Physics {
        }
      }
    }
    DEF WHEEL_2 HingeJoint {
      jointParameters HingeJointParameters {
        position 8.812182835959432e-07
        anchor 0 -0.12 -0.04
      }
      device [
        RotationalMotor {
          name "left wheel motor"
        }
      ]
      endPoint DEF WHEEL_22 Solid {
        translation 0.019999999999999952 -0.11999998237563432 -0.059999999999992226
        rotation 0.9999999999999999 0 0 1.5708005751036815
        children [
          USE WHEEL2
        ]
        boundingObject USE WHEEL2
        physics Physics {
        }
      }
    }
    DEF BODY2 Shape {
      appearance PBRAppearance {
        baseColor 1 0.7 0
        roughness 1
        metalness 0
      }
      geometry Cylinder {
        height 0.2
        radius 0.1
      }
    }
  ]
  name "robot(1)"
  boundingObject USE BODY2
  physics Physics {
  }
  controller "my_controller"
}
Robot {
  translation 1.161753044530221 0.029729490070962396 -0.0018228168120079393
  rotation -2.0922936710122738e-10 0.9999999999998591 -5.308538867714417e-07 0.0007884571774692758
  children [
    DEF BODY Shape {
      appearance PBRAppearance {
        baseColor 0.7 0.5 0.8
        metalness 0
      }
      geometry Cylinder {
        height 0.05
        radius 0.1
      }
    }
    Camera {
      translation 0 0 0.1
      rotation 0 1 0 3.14159
      children [
        Shape {
          appearance PBRAppearance {
          }
          geometry Sphere {
            radius 0.01
            subdivision 2
          }
        }
      ]
      fieldOfView 2
      width 188
      height 120
    }
    Lidar {
      translation 0 0.025 0.1
      rotation 0 1 0 3.141592653589793
    }
    DEF CASTER_WHEEL_BACK Solid {
      translation 0 -0.02 -0.075
      children [
        Shape {
          appearance PBRAppearance {
          }
          geometry DEF CASTER_GEOMETRY Sphere {
            radius 0.01
            subdivision 2
          }
        }
      ]
      boundingObject USE CASTER_GEOMETRY
      physics DEF CASTER_PHYSICS Physics {
      }
    }
    DEF CASTER_WHEEL_FRONT Solid {
      translation 0 -0.02 0.075
      children [
        Shape {
          appearance PBRAppearance {
          }
          geometry DEF CASTER_GEOMETRY Sphere {
            radius 0.01
            subdivision 2
          }
        }
      ]
      name "solid(1)"
      boundingObject USE CASTER_GEOMETRY
      physics USE CASTER_PHYSICS
    }
    HingeJoint {
      jointParameters HingeJointParameters {
        position 1.1274269149685906e-09
        anchor -0.09 -0.01 0
      }
      device [
        RotationalMotor {
          name "right wheel motor"
        }
        PositionSensor {
          name "right wheel sensor"
        }
      ]
      endPoint DEF WHEEL_RIGHT Solid {
        translation -0.09 -0.01 0
        rotation 4.9332755149928136e-09 -4.933293077827115e-09 1 1.5707999999998663
        children [
          DEF WHEEL_SHAPE Shape {
            geometry Cylinder {
              height 0.005
              radius 0.02
            }
          }
        ]
        name "solid(3)"
        boundingObject USE WHEEL_SHAPE
        physics DEF WHEEL_PHYSICS Physics {
        }
      }
    }
    HingeJoint {
      jointParameters HingeJointParameters {
        position -1.6661841508551552e-12
        anchor 0.09 -0.01 0
      }
      device [
        RotationalMotor {
          name "left wheel motor"
        }
        PositionSensor {
          name "left wheel sensor"
        }
      ]
      endPoint DEF WHEEL_LEFT Solid {
        translation 0.09 -0.01 0
        rotation 5.202377159132063e-10 -5.202389562469383e-10 1 1.570799693899447
        children [
          USE WHEEL_SHAPE
        ]
        name "solid(2)"
        boundingObject USE WHEEL_SHAPE
        physics USE WHEEL_PHYSICS
      }
    }
  ]
  name "robot(2)"
  boundingObject USE BODY
  physics Physics {
    density -1
    mass 1
  }
  controller "my_controller"
}
